<?xml version="1.0" ?>
<!-- =================================================================================== -->
<!-- |    This document was autogenerated by xacro from jubot_box.xacro                | -->
<!-- |    EDITING THIS FILE BY HAND IS NOT RECOMMENDED                                 | -->
<!-- =================================================================================== -->
<robot name="jubox">
  <!-- <xacro:property name="footprint_radius" value="0.001" /> -->
  <!--footprint-->
  <!-- <link name="base_footprint">
        <visual>
            <geometry>
                <sphere radius="${footprint_radius}"/>
            </geometry>
        </visual>        
    </link>
    <joint name="base2footprint" type="fixed">
        <origin xyz="0.0 0.0 0.08" rpy="0.0 0.0 0.0"/>
        <parent link="base_footprint"/>
        <child link="base_link"/> 
    </joint>-->
  <!--base_car-->
  <link name="base_link">
    <visual>
      <origin rpy="0.0 0.0 0.0" xyz="0.0 0.0 0.12"/>
      <geometry>
        <box size="0.67 0.53 0.10"/>
      </geometry>
      <material name="white">
        <color rgba="1 1 1 1"/>
      </material>
    </visual>
    <collision>
      <geometry>
        <box size="0.67 0.53 0.10"/>
      </geometry>
      <origin rpy="0.0 0.0 0.0" xyz="0.0 0.0 0.0"/>
    </collision>
    <inertial>
      <mass value="2"/>
      <inertia ixx="0.07648333333333335" ixy="0" ixz="0" iyy="0.12163333333333336" iyz="0" izz="0.048483333333333344"/>
    </inertial>
  </link>
  <gazebo reference="base_link">
    <material>Gazebo/White</material>
  </gazebo>
  <joint name="left_back_joint" type="continuous">
    <origin rpy="1.57079635 0.0 0.0" xyz="-0.2 0.298 0.07"/>
    <parent link="base_link"/>
    <child link="left_back_link"/>
    <axis xyz="0 0 1"/>
  </joint>
  <link name="left_back_link">
    <visual>
      <origin rpy="0.0 0.0 0.0" xyz="0.0 0.0 0.0"/>
      <geometry>
        <cylinder length="0.04" radius="0.13"/>
      </geometry>
      <material name="black">
        <color rgba="0 0 0 1"/>
      </material>
    </visual>
    <collision>
      <geometry>
        <cylinder length="0.04" radius="0.13"/>
      </geometry>
      <origin rpy="0.0 0.0 0.0" xyz="0.0 0.0 0.0"/>
    </collision>
    <inertial>
      <mass value="0.05"/>
      <inertia ixx="0.0002179166666666667" ixy="0" ixz="0" iyy="0.0002179166666666667" iyz="0" izz="0.0004225000000000001"/>
    </inertial>
  </link>
  <gazebo reference="left_back_link">
    <material>Gazebo/Black</material>
  </gazebo>
  <joint name="right_back_joint" type="continuous">
    <origin rpy="1.57079635 0.0 0.0" xyz="-0.2 -0.298 0.07"/>
    <parent link="base_link"/>
    <child link="right_back_link"/>
    <axis xyz="0 0 1"/>
  </joint>
  <link name="right_back_link">
    <visual>
      <origin rpy="0.0 0.0 0.0" xyz="0.0 0.0 0.0"/>
      <geometry>
        <cylinder length="0.04" radius="0.13"/>
      </geometry>
      <material name="black">
        <color rgba="0 0 0 1"/>
      </material>
    </visual>
    <collision>
      <geometry>
        <cylinder length="0.04" radius="0.13"/>
      </geometry>
      <origin rpy="0.0 0.0 0.0" xyz="0.0 0.0 0.0"/>
    </collision>
    <inertial>
      <mass value="0.05"/>
      <inertia ixx="0.0002179166666666667" ixy="0" ixz="0" iyy="0.0002179166666666667" iyz="0" izz="0.0004225000000000001"/>
    </inertial>
  </link>
  <gazebo reference="right_back_link">
    <material>Gazebo/Black</material>
  </gazebo>
  <joint name="left_front_joint" type="continuous">
    <origin rpy="1.57079635 0.0 0.0" xyz="0.2 0.298 0.07"/>
    <parent link="base_link"/>
    <child link="left_front_link"/>
    <axis xyz="0 0 1"/>
  </joint>
  <link name="left_front_link">
    <visual>
      <origin rpy="0.0 0.0 0.0" xyz="0.0 0.0 0.0"/>
      <geometry>
        <cylinder length="0.04" radius="0.13"/>
      </geometry>
      <material name="black">
        <color rgba="0 0 0 1"/>
      </material>
    </visual>
    <collision>
      <geometry>
        <cylinder length="0.04" radius="0.13"/>
      </geometry>
      <origin rpy="0.0 0.0 0.0" xyz="0.0 0.0 0.0"/>
    </collision>
    <inertial>
      <mass value="0.05"/>
      <inertia ixx="0.0002179166666666667" ixy="0" ixz="0" iyy="0.0002179166666666667" iyz="0" izz="0.0004225000000000001"/>
    </inertial>
  </link>
  <gazebo reference="left_front_link">
    <material>Gazebo/Black</material>
  </gazebo>
  <joint name="right_front_joint" type="continuous">
    <origin rpy="1.57079635 0.0 0.0" xyz="0.2 -0.298 0.07"/>
    <parent link="base_link"/>
    <child link="right_front_link"/>
    <axis xyz="0 0 1"/>
  </joint>
  <link name="right_front_link">
    <visual>
      <origin rpy="0.0 0.0 0.0" xyz="0.0 0.0 0.0"/>
      <geometry>
        <cylinder length="0.04" radius="0.13"/>
      </geometry>
      <material name="black">
        <color rgba="0 0 0 1"/>
      </material>
    </visual>
    <collision>
      <geometry>
        <cylinder length="0.04" radius="0.13"/>
      </geometry>
      <origin rpy="0.0 0.0 0.0" xyz="0.0 0.0 0.0"/>
    </collision>
    <inertial>
      <mass value="0.05"/>
      <inertia ixx="0.0002179166666666667" ixy="0" ixz="0" iyy="0.0002179166666666667" iyz="0" izz="0.0004225000000000001"/>
    </inertial>
  </link>
  <gazebo reference="right_front_link">
    <material>Gazebo/Black</material>
  </gazebo>
  <!--support-->
  <joint name="right_front_joint2" type="fixed">
    <origin rpy="1.57079635 0.0 0.0" xyz="0.3 -0.24 0.22"/>
    <parent link="base_link"/>
    <child link="right_front_link2"/>
  </joint>
  <link name="right_front_link2">
    <visual>
      <origin rpy="0.0 0.0 0.0" xyz="0.0 0.0 0.0"/>
      <geometry>
        <box size="0.04 0.11 0.04"/>
      </geometry>
      <material name="white">
        <color rgba="1 1 1 0"/>
      </material>
    </visual>
    <collision>
      <geometry>
        <box size="0.04 0.11 0.04"/>
      </geometry>
      <origin rpy="0.0 0.0 0.0" xyz="0.0 0.0 0.0"/>
    </collision>
    <inertial>
      <mass value="0.02"/>
      <inertia ixx="2.2833333333333334e-05" ixy="0" ixz="0" iyy="5.3333333333333345e-06" iyz="0" izz="2.2833333333333334e-05"/>
    </inertial>
  </link>
  <gazebo reference="right_front_link2">
    <material>Gazebo/White</material>
  </gazebo>
  <joint name="left_front_joint2" type="fixed">
    <origin rpy="1.57079635 0.0 0.0" xyz="0.3 0.24 0.22"/>
    <parent link="base_link"/>
    <child link="left_front_link2"/>
  </joint>
  <link name="left_front_link2">
    <visual>
      <origin rpy="0.0 0.0 0.0" xyz="0.0 0.0 0.0"/>
      <geometry>
        <box size="0.04 0.11 0.04"/>
      </geometry>
      <material name="white">
        <color rgba="1 1 1 0"/>
      </material>
    </visual>
    <collision>
      <geometry>
        <box size="0.04 0.11 0.04"/>
      </geometry>
      <origin rpy="0.0 0.0 0.0" xyz="0.0 0.0 0.0"/>
    </collision>
    <inertial>
      <mass value="0.02"/>
      <inertia ixx="2.2833333333333334e-05" ixy="0" ixz="0" iyy="5.3333333333333345e-06" iyz="0" izz="2.2833333333333334e-05"/>
    </inertial>
  </link>
  <gazebo reference="left_front_link2">
    <material>Gazebo/White</material>
  </gazebo>
  <joint name="left_back_joint2" type="fixed">
    <origin rpy="1.57079635 0.0 0.0" xyz="-0.3 0.24 0.22"/>
    <parent link="base_link"/>
    <child link="left_back_link2"/>
  </joint>
  <link name="left_back_link2">
    <visual>
      <origin rpy="0.0 0.0 0.0" xyz="0.0 0.0 0.0"/>
      <geometry>
        <box size="0.04 0.11 0.04"/>
      </geometry>
      <material name="white">
        <color rgba="1 1 1 0"/>
      </material>
    </visual>
    <collision>
      <geometry>
        <box size="0.04 0.11 0.04"/>
      </geometry>
      <origin rpy="0.0 0.0 0.0" xyz="0.0 0.0 0.0"/>
    </collision>
    <inertial>
      <mass value="0.02"/>
      <inertia ixx="2.2833333333333334e-05" ixy="0" ixz="0" iyy="5.3333333333333345e-06" iyz="0" izz="2.2833333333333334e-05"/>
    </inertial>
  </link>
  <gazebo reference="left_back_link2">
    <material>Gazebo/White</material>
  </gazebo>
  <joint name="right_back_joint2" type="fixed">
    <origin rpy="1.57079635 0.0 0.0" xyz="-0.3 -0.24 0.22"/>
    <parent link="base_link"/>
    <child link="right_back_link2"/>
  </joint>
  <link name="right_back_link2">
    <visual>
      <origin rpy="0.0 0.0 0.0" xyz="0.0 0.0 0.0"/>
      <geometry>
        <box size="0.04 0.11 0.04"/>
      </geometry>
      <material name="white">
        <color rgba="1 1 1 0"/>
      </material>
    </visual>
    <collision>
      <geometry>
        <box size="0.04 0.11 0.04"/>
      </geometry>
      <origin rpy="0.0 0.0 0.0" xyz="0.0 0.0 0.0"/>
    </collision>
    <inertial>
      <mass value="0.02"/>
      <inertia ixx="2.2833333333333334e-05" ixy="0" ixz="0" iyy="5.3333333333333345e-06" iyz="0" izz="2.2833333333333334e-05"/>
    </inertial>
  </link>
  <gazebo reference="right_back_link2">
    <material>Gazebo/White</material>
  </gazebo>
  <!--base2_link-->
  <joint name="base2_joint" type="fixed">
    <origin rpy="0 0.0 0.0" xyz="0 0 0.27"/>
    <parent link="base_link"/>
    <child link="base2_link"/>
  </joint>
  <link name="base2_link">
    <visual>
      <origin rpy="0.0 0.0 0.0" xyz="0.0 0.0 0.0"/>
      <geometry>
        <box size="0.67 0.53 0.08"/>
      </geometry>
      <material name="white">
        <color rgba="1 1 1 0"/>
      </material>
    </visual>
    <collision>
      <geometry>
        <box size="0.67 0.53 0.08"/>
      </geometry>
      <origin rpy="0.0 0.0 0.0" xyz="0.0 0.0 0.0"/>
    </collision>
    <inertial>
      <mass value="1"/>
      <inertia ixx="0.03794166666666667" ixy="0" ixz="0" iyy="0.06081666666666668" iyz="0" izz="0.02394166666666667"/>
    </inertial>
  </link>
  <gazebo reference="base2_link">
    <material>Gazebo/White</material>
  </gazebo>
  <!-- 支架安装的z坐标:底盘高度 / 2 + 支架高度 / 2  -->
  <link name="support">
    <visual>
      <geometry>
        <cylinder length="0.15" radius="0.01"/>
      </geometry>
      <origin rpy="0.0 0.0 0.0" xyz="0.0 0.0 0.0"/>
      <material name="red">
        <color rgba="0.8 0.2 0.0 0.8"/>
      </material>
    </visual>
  </link>
  <joint name="support2base_link" type="fixed">
    <parent link="base2_link"/>
    <child link="support"/>
    <origin xyz="0.0 0.0 0.11499999999999999"/>
  </joint>
  <joint name="laser_joint" type="fixed">
    <origin rpy="0.0 0.0 0.0" xyz="0.0 0.0 0.06"/>
    <parent link="support"/>
    <child link="laser"/>
  </joint>
  <link name="laser">
    <visual>
      <origin rpy="0.0 0.0 0.0" xyz="0.0 0.0 0.0"/>
      <geometry>
        <cylinder length="0.04" radius="0.06"/>
      </geometry>
      <material name="black">
        <color rgba="0 0 0 0.7"/>
      </material>
    </visual>
    <collision>
      <geometry>
        <cylinder length="0.04" radius="0.06"/>
      </geometry>
      <origin rpy="0.0 0.0 0.0" xyz="0.0 0.0 0.0"/>
    </collision>
    <inertial>
      <mass value="0.06"/>
      <inertia ixx="6.2e-05" ixy="0" ixz="0" iyy="6.2e-05" iyz="0" izz="0.000108"/>
    </inertial>
  </link>
  <gazebo reference="laser">
    <material>Gazebo/Black</material>
  </gazebo>
  <joint name="camera_joint" type="continuous">
    <origin rpy="0.0 0.0 0.0" xyz="0.28500000000000003 0.0 0.06"/>
    <parent link="base2_link"/>
    <child link="camera"/>
  </joint>
  <link name="camera">
    <visual>
      <origin rpy="0.0 0.0 0.0" xyz="0.0 0.0 0.0"/>
      <geometry>
        <box size="0.02 0.08 0.04"/>
      </geometry>
      <material name="blue">
        <color rgba="0.0 0.0 1.0 0.9"/>
      </material>
    </visual>
    <collision>
      <geometry>
        <box size="0.02 0.08 0.04"/>
      </geometry>
      <origin rpy="0.0 0.0 0.0" xyz="0.0 0.0 0.0"/>
    </collision>
    <inertial>
      <mass value="0.02"/>
      <inertia ixx="3.3333333333333337e-06" ixy="0" ixz="0" iyy="1.1333333333333336e-05" iyz="0" izz="1.3333333333333335e-05"/>
    </inertial>
  </link>
  <gazebo reference="camera">
    <material>Gazebo/Blue</material>
  </gazebo>
</robot>

